<?xml version="1.0" encoding="UTF-8"?>
<!-- Generated by org.testng.reporters.JUnitReportReporter -->
<testsuite skipped="0" hostname="360NDCPC104" name="Runners.Fix" tests="1" failures="0" timestamp="24 Apr 2019 03:43:24 GMT" time="56.451" errors="1">
  <testcase name="feature" time="56.451" classname="Runners.Fix">
    <error type="cucumber.runtime.CucumberException" message="junit.framework.AssertionFailedError: Issues is updated">
      <![CDATA[cucumber.runtime.CucumberException: junit.framework.AssertionFailedError: Issues is updated
at cucumber.api.testng.TestNGCucumberRunner.runCucumber(TestNGCucumberRunner.java:69)
at cucumber.api.testng.AbstractTestNGCucumberTests.feature(AbstractTestNGCucumberTests.java:21)
at sun.reflect.NativeMethodAccessorImpl.invoke0(Native Method)
at sun.reflect.NativeMethodAccessorImpl.invoke(Unknown Source)
at sun.reflect.DelegatingMethodAccessorImpl.invoke(Unknown Source)
at java.lang.reflect.Method.invoke(Unknown Source)
at org.testng.internal.MethodInvocationHelper.invokeMethod(MethodInvocationHelper.java:124)
at org.testng.internal.Invoker.invokeMethod(Invoker.java:580)
at org.testng.internal.Invoker.invokeTestMethod(Invoker.java:716)
at org.testng.internal.Invoker.invokeTestMethods(Invoker.java:988)
at org.testng.internal.TestMethodWorker.invokeTestMethods(TestMethodWorker.java:125)
at org.testng.internal.TestMethodWorker.run(TestMethodWorker.java:109)
at org.testng.TestRunner.privateRun(TestRunner.java:648)
at org.testng.TestRunner.run(TestRunner.java:505)
at org.testng.SuiteRunner.runTest(SuiteRunner.java:455)
at org.testng.SuiteRunner.runSequentially(SuiteRunner.java:450)
at org.testng.SuiteRunner.privateRun(SuiteRunner.java:415)
at org.testng.SuiteRunner.run(SuiteRunner.java:364)
at org.testng.SuiteRunnerWorker.runSuite(SuiteRunnerWorker.java:52)
at org.testng.SuiteRunnerWorker.run(SuiteRunnerWorker.java:84)
at org.testng.TestNG.runSuitesSequentially(TestNG.java:1208)
at org.testng.TestNG.runSuitesLocally(TestNG.java:1137)
at org.testng.TestNG.runSuites(TestNG.java:1049)
at org.testng.TestNG.run(TestNG.java:1017)
at org.testng.remote.AbstractRemoteTestNG.run(AbstractRemoteTestNG.java:114)
at org.testng.remote.RemoteTestNG.initAndRun(RemoteTestNG.java:251)
at org.testng.remote.RemoteTestNG.main(RemoteTestNG.java:77)
Caused by: junit.framework.AssertionFailedError: Issues is updated
at junit.framework.Assert.fail(Assert.java:47)
at junit.framework.Assert.assertTrue(Assert.java:20)
at StepsDefinationsHelper.FixPage_Helper.VerifyNextstage(FixPage_Helper.java:50)
at StepsDefinations.Fix_Page_Step_defination.open_Assignment_updated_as_Customer_satisfaction_Resolved(Fix_Page_Step_defination.java:73)
at âœ½.Then Open Assignment updated as Customer satisfaction (Resolved)(src/FeatureFiles/Fix.feature:19)
]]>
    </error>
  </testcase> <!-- feature -->
</testsuite> <!-- Runners.Fix -->
